Workbook

Sheet Kapak
B1: BÜTÇE TEKLİF FORMU
B2: Marka Yeniden İnşa + İletişim Sistemi
B4: MARKA | C4: Özgür Irmak Protez ve Ortez Merkezi
B5: AJANS | C5: Steps on Clouds
B6: HAZIRLAYAN | C6: Ayhan Erden
B7: TARİH
B8: GEÇERLİLİK | C8: Teklif tarihinden itibaren 7 gün
B9: PARA BİRİMİ | C9: [TL / Döviz — netleşecek]
B11: ÖZET | E11: Toplam
B12: 1 · Kurumsal Çekirdek (Marka Kimliği) | D12: tek seferlik | E12: ='Bütçe Dökümü'!E14
B13: 2 · Sistem — Web Sitesi (Wix) | D13: tek seferlik | E13: ='Bütçe Dökümü'!E27
B14: 3 · Sistem — Sosyal Medya Kurulumu | D14: tek seferlik | E14: ='Bütçe Dökümü'!E33
B15: 4 · Sistem — Kampanya Çekimi (D1) | D15: tek seferlik | E15: ='Bütçe Dökümü'!E45
B16: TEK SEFERLİK GENEL TOPLAM (KDV hariç) | E16: ='Bütçe Dökümü'!E50
B18: 5 · Aylık — Strateji + Görsel İçerik | D18: / ay | E18: ='Bütçe Dökümü'!E60
B19: Aylık Dönem Toplamı | E19: ='Bütçe Dökümü'!E61
B21: YAPILACAK İŞE İLİŞKİN ESASLAR
B22: ► Bedeller KDV hariçtir (+KDV).
B23: ► Tek seferlik kalemler: %50 avans, kalan teslimde / 30 gün. Aylık: ayın 1'inde.
B24: ► Bu teklif, veriliş tarihinden itibaren 7 gün geçerlidir.
B25: ► Kampanya çekimi telifi 5846 sayılı FSEK'e tabidir; eser sahibi Ayhan Erden. Detay döküm ayrı çekim bütçe formunda.
B26: ► Yurtdışı / global kullanım (web + 4 ülke sosyal + reklam) için global kullanım telifi uygulanır.
B27: ► HUKUK GATE: Web ve tüm medikal içerik, yayından önce avukat onayından geçer (Sağlık Bakanlığı sağlık reklamı mevzuatı). İçerik/yayın uyumu bu teklif kapsamı dışındadır (avukat müşteri tarafında).
B28: ► Kapsam dışı (ayrı bütçe): ek prodüksiyon/çekim, reklam medya bütçesi, günlük topluluk yönetimi, fiziksel baskı.
B29: ► Marka adı korunur; ozgurprotez + biyonikprotezler tek master-brand altında birleşir (öneri).
B30: ► Bütçe onayından sonra yapılacak değişiklikler bütçeyi -/+ etkiler.
B31: ► Teklif imza onaylı geri gönderildiğinde kabul edilmiş sayılır.
B33: Onay (İmza):

Sheet Bütçe Dökümü
B1: 1 · KURUMSAL ÇEKİRDEK (Marka Kimliği) — tek seferlik
B2: Kalem | C2: Adet | D2: Birim Fiyatı | E2: Toplam
B3: Konumlandırma & strateji | C3: 1 | E3: =C3*D3
B4: Mesaj mimarisi (TR/EN/AR/RU) | C4: 1 | E4: =C4*D4
B5: Marka sesi & ton rehberi | C5: 1 | E5: =C5*D5
B6: İsim, tagline & marka mimarisi (tek master-brand) | C6: 1 | E6: =C6*D6
B7: Logo tasarımı + varyasyonlar | C7: 1 | E7: =C7*D7
B8: Logo do's / don'ts | C8: 1 | E8: =C8*D8
B9: Renk paleti | C9: 1 | E9: =C9*D9
B10: Tipografi sistemi (Latin+Kiril+Arap) | C10: 1 | E10: =C10*D10
B11: Görsel dil / art direction | C11: 1 | E11: =C11*D11
B12: Brand guide (marka kılavuzu) | C12: 1 | E12: =C12*D12
B13: Temel uygulama şablonları | C13: 1 | E13: =C13*D13
D14: ÇEKİRDEK TOPLAM | E14: =SUM(E3:E13)
B16: 2 · SİSTEM — Web Sitesi (Wix) — tek seferlik
B17: Kalem | C17: Adet | D17: Birim Fiyatı | E17: Toplam
B18: Site haritası & yapı (4 dil + AR RTL) | C18: 1 | E18: =C18*D18
B19: İçerik yazımı (compliance-aware) | C19: 1 | E19: =C19*D19
B20: Çeviri / lokalizasyon (EN/AR/RU) | C20: 1 | E20: =C20*D20
B21: UI tasarım | C21: 1 | E21: =C21*D21
B22: Geliştirme & responsive (Wix) | C22: 1 | E22: =C22*D22
B23: SEO temel kurulum | C23: 1 | E23: =C23*D23
B24: İletişim / randevu entegrasyonu | C24: 1 | E24: =C24*D24
B25: Yasal sayfalar (KVKK/çerez/gizlilik) | C25: 1 | E25: =C25*D25
B26: Test & yayın (avukat onayı sonrası) | C26: 1 | E26: =C26*D26
D27: WEB TOPLAM | E27: =SUM(E18:E26)
B29: 3 · SİSTEM — Sosyal Medya Kurulumu — tek seferlik
B30: Kalem | C30: Adet | D30: Birim Fiyatı | E30: Toplam
B31: Profil optimizasyonu (YouTube/IG/FB/LinkedIn) | C31: 1 | E31: =C31*D31
B32: Platform görsel kiti + gönderi şablonları | C32: 1 | E32: =C32*D32
D33: SOSYAL KURULUM TOPLAM | E33: =SUM(E31:E32)
B35: 4 · SİSTEM — Kampanya Çekimi (D1) — tek seferlik
B36: Kalem | C36: Adet | D36: Birim Fiyatı | E36: Toplam
B37: Yaratıcı yön + brief (çekirdek görsel dili) | C37: 1 | E37: =C37*D37
B38: Çekim: fotoğraf + ~4 dk marka filmi | C38: 1 | E38: =C38*D38
B39: Video ekibi (yönetmen / görüntü yön. / asistan / drone) | C39: 1 | E39: =C39*D39
B40: Post: kurgu / renk / ses-müzik lisansı / retouch | C40: 1 | E40: =C40*D40
B41: Altyazı / lokalizasyon (TR/EN/AR/RU) | C41: 1 | E41: =C41*D41
B42: Cast: gerçek hasta (izin / telif) | C42: 1 | E42: =C42*D42
B43: Mekan / lojistik / catering | C43: 1 | E43: =C43*D43
...
